Workbook

Sheet Summary
A1: Territorial units by provisional functional economic region
A2: Preferred scenario: right-bank / government-administered territory, 2024 population reference
A4: Region ID | B4: Functional region | C4: Base analytical units | D4: Population 2024 | E4: Share of included population
A5: RBR01 | B5: Chișinău–Centre | C5: =COUNTA('Chisinau-Centre'!$A$5:$A$213) -> 209 | D5: =SUM('Chisinau-Centre'!$E$5:$E$213) -> 1131229 | E5: =D5/SUM($D$5:$D$11) -> 0.47183809
A6: RBR02 | B6: Bălți–North | C6: =COUNTA('Balti-North'!$A$5:$A$210) -> 206 | D6: =SUM('Balti-North'!$E$5:$E$210) -> 438210 | E6: =D6/SUM($D$5:$D$11) -> 0.18277835
A7: RBR03 | B7: Ungheni–West | C7: =COUNTA('Ungheni-West'!$A$5:$A$69) -> 65 | D7: =SUM('Ungheni-West'!$E$5:$E$69) -> 123392 | E7: =D7/SUM($D$5:$D$11) -> 0.051467074
A8: RBR04 | B8: Soroca–North-East | C8: =COUNTA('Soroca-NE'!$A$5:$A$127) -> 123 | D8: =SUM('Soroca-NE'!$E$5:$E$127) -> 173723 | E8: =D8/SUM($D$5:$D$11) -> 0.072460244
A9: RBR05 | B9: Orhei–Centre-North | C9: =COUNTA('Orhei-Centre-N'!$A$5:$A$144) -> 140 | D9: =SUM('Orhei-Centre-N'!$E$5:$E$144) -> 207100 | E9: =D9/SUM($D$5:$D$11) -> 0.086381864
A10: RBR06 | B10: Cahul–South-West | C10: =COUNTA('Cahul-SW'!$A$5:$A$69) -> 65 | D10: =SUM('Cahul-SW'!$E$5:$E$69) -> 132946 | E10: =D10/SUM($D$5:$D$11) -> 0.055452068
A11: RBR07 | B11: Comrat–South-East | C11: =COUNTA('Comrat-SE'!$A$5:$A$100) -> 96 | D11: =SUM('Comrat-SE'!$E$5:$E$100) -> 190894 | E11: =D11/SUM($D$5:$D$11) -> 0.079622306
A12: Total included | C12: =SUM(C5:C11) -> 904 | D12: =SUM(D5:D11) -> 2397494 | E12: =SUM(E5:E11) -> 1
A14: Interpretation note
A15: These are the base locality/commune polygons used by the model, not a new official administrative classification. Distance is measured along the fastest modelled OSM road route. Rows marked 'Straight-line fallback' have no usable network path within the 300-minute routing search and use straight-line distance instead.
A19: Source: right_bank_assignments.csv and local_unit_assignments.csv in the Moldova functional geography GIS package.

Sheet Chisinau-Centre
A1: RBR01 · Chișinău–Centre
A2: Preferred scenario: right-bank / government-administered territory, 2024 population reference
A4: No. | B4: District / municipality | C4: Territorial unit | D4: CUATM | E4: Population 2024 | F4: Micro-region ID | G4: Micro-region centre | H4: Travel time to regional anchor (min) | I4: Route distance to regional anchor (km) | J4: Route calculation
A5: 1 | B5: Mun. Chișinău | C5: Budeşti | D5: 143000 | E5: 4425 | F5: RBM02 | G5: Chișinău | H5: 19.1 | I5: 18.2 | J5: Fastest OSM road route
A6: 2 | B6: Mun. Chișinău | C6: Coloniţa | D6: 144000 | E6: 3956 | F6: RBM02 | G6: Chișinău | H6: 12 | I6: 11.2 | J6: Fastest OSM road route
A7: 3 | B7: Mun. Chișinău | C7: com. Băcioi | D7: 112000 | E7: 11663 | F7: RBM32 | G7: com. Răzeni | H7: 16.6 | I7: 15.6 | J7: Fastest OSM road route
A8: 4 | B8: Mun. Chișinău | C8: com. Bubuieci | D8: 142000 | E8: 11152 | F8: RBM02 | G8: Chișinău | H8: 15.2 | I8: 12.9 | J8: Fastest OSM road route
A9: 5 | B9: Mun. Chișinău | C9: com. Ciorescu | D9: 152000 | E9: 6714 | F9: RBM02 | G9: Chișinău | H9: 14.6 | I9: 15.1 | J9: Fastest OSM road route
A10: 6 | B10: Mun. Chișinău | C10: com. Cruzeşti | D10: 145000 | E10: 1709 | F10: RBM02 | G10: Chișinău | H10: 18.6 | I10: 17.6 | J10: Fastest OSM road route
A11: 7 | B11: Mun. Chișinău | C11: com. Grătieşti | D11: 153000 | E11: 7299 | F11: RBM02 | G11: Chișinău | H11: 13.6 | I11: 10.8 | J11: Fastest OSM road route
A12: 8 | B12: Mun. Chișinău | C12: com. Stăuceni | D12: 154000 | E12: 11210 | F12: RBM02 | G12: Chișinău | H12: 11.3 | I12: 10.1 | J12: Fastest OSM road route
A13: 9 | B13: Mun. Chișinău | C13: com. Tohatin | D13: 146000 | E13: 4045 | F13: RBM02 | G13: Chișinău | H13: 15.4 | I13: 13.6 | J13: Fastest OSM road route
A14: 10 | B14: Mun. Chișinău | C14: com. Truşeni | D14: 126000 | E14: 10937 | F14: RBM02 | G14: Chișinău | H14: 13.5 | I14: 12.8 | J14: Fastest OSM road route
A15: 11 | B15: Mun. Chișinău | C15: Condriţa | D15: 123000 | E15: 547 | F15: RBM02 | G15: Chișinău | H15: 23.8 | I15: 26.2 | J15: Fastest OSM road route
A16: 12 | B16: Mun. Chișinău | C16: Ghidighici | D16: 125000 | E16: 5240 | F16: RBM02 | G16: Chișinău | H16: 11 | I16: 9.7 | J16: Fastest OSM road route
... A48: 44 | B48: Raionul Anenii Noi | C48: Şerpeni | D48: 1030000 | E48: 2094 | F48: RBM19 | G48: or. Anenii Noi | H48: 52.4 | I48: 62.4 | J48: Fastest OSM road route
A49: 45 | B49: Raionul Anenii Noi | C49: Țînțăreni | E49: 0 | F49: RBM19 | G49: or. Anenii Noi | H49: 35.6 | I49: 35 | J49: Fastest OSM road route
A50: 46 | B50: Raionul Anenii Noi | C50: Varniţa | D50: 1033000 | E50: 3827 | F50: RBM19 | G50: or. Anenii Noi | H50: 56.3 | I50: 65.7 | J50: Fastest OSM road route
A51: 47 | B51: Raionul Călăraşi | C51: Căbăieşti | D51: 2513000 | E51: 526 | F51: RBM18 | G51: or. Călăraşi | H51: 59.5 | I51: 65.5 | J51: Fastest OSM road route
A52: 48 | B52: Raionul Călăraşi | C52: com. Buda | D52: 2512000 | E52: 772 | F52: RBM18 | G52: or. Călăraşi | H52: 53.2 | I52: 59.7 | J52: Fastest OSM road route
A53: 49 | B53: Raionul Călăraşi | C53: com. Tuzara | D53: 2532000 | E53: 1706 | F53: RBM18 | G53: or. Călăraşi | H53: 44.1 | I53: 51.3 | J53: Fastest OSM road route
A54: 50 | B54: Raionul Călăraşi | C54: Horodişte | D54: 2519000 | E54: 1619 | F54: RBM18 | G54: or. Călăraşi | H54: 47.6 | I54: 56.4 | J54: Fastest OSM road route
A55: 51 | B55: Raionul Călăraşi | C55: Nişcani | D55: 2521000 | E55: 1021 | F55: RBM18 | G55: or. Călăraşi | H55: 37.9 | I55: 45.6 | J55: Fastest OSM road route
A56: 52 | B56: Raionul Călăraşi | C56: or. Călăraşi | D56: 2501000 | E56: 9469 | F56: RBM18 | G56: or. Călăraşi | H56: 44.1 | I56: 51.2 | J56: Fastest OSM road route
A57: 53 | B57: Raionul Călăraşi | C57: Păuleşti | D57: 2523000 | E57: 547 | F57: RBM18 | G57: or. Călăraşi | H57: 45.3 | I57: 51 | J57: Fastest OSM road route
A58: 54 | B58: Raionul Călăraşi | C58: Peticeni | D58: 2523100 | E58: 820 | F58: RBM18 | G58: or. Călăraşi | H58: 49.4 | I58: 57.1 | J58: Fastest OSM road route
A59: 55 | B59: Raionul Călăraşi | C59: Pituşca | D59: 2524000 | E59: 1796 | F59: RBM18 | G59: or. Călăraşi | H59: 41 | I59: 45.9 | J59: Fastest OSM road route
A60: 56 | B60: Raionul Călăraşi | C60: Pîrjolteni | D60: 2525000 | E60: 932 | F60: RBM18 | G60: or. Călăraşi | H60: 50 | I60: 54.8 | J60: Fastest OSM road route
A61: 57 | B61: Raionul Călăraşi | C61: Sadova | D61: 2528000 | E61: 1422 | F61: RBM18 | G61: or. Călăraşi | H61: 37.7 | I61: 45.4 | J61: Fastest OSM road route
... A76: 72 | B76: Raionul Căuşeni | C76: Coşcalia | D76: 2719000 | E76: 1366 | F76: RBM09 | G76: or. Căuşeni | H76: 55.1 | I76: 63.6 | J76: Fastest OSM road route
A77: 73 | B77: Raionul Căușeni | C77: Gîsca | E77: 0 | F77: RBM19 | G77: or. Anenii Noi | H77: 65.1 | I77: 70.2 | J77: Fastest OSM road route
A78: 74 | B78: Raionul Căuşeni | C78: Grigorievca | D78: 2724000 | E78: 855 | F78: RBM09 | G78: or. Căuşeni | H78: 59.9 | I78: 65.1 | J78: Fastest OSM road route
A79: 75 | B79: Raionul Căuşeni | C79: Hagimus | D79: 2725000 | E79: 2054 | F79: RBM09 | G79: or. Căuşeni | H79: 73.6 | I79: 79 | J79: Fastest OSM road route
A80: 76 | B80: Raionul Căuşeni | C80: or. Căinari | D80: 2702000 | E80: 2135 | F80: RBM32 | G80: com. Răzeni | H80: 44.3 | I80: 52.1 | J80: Fastest OSM road route
A81: 77 | B81: Raionul Căuşeni | C81: or. Căuşeni | D81: 2701000 | E81: 13458 | F81: RBM09 | G81: or. Căuşeni | H81: 73.4 | I81: 78.5 | J81: Fastest OSM road route
A82: 78 | B82: Raionul Căuşeni | C82: Plop-Ştiubei | D82: 2728000 | E82: 1222 | F82: RBM09 | G82: or. Căuşeni | H82: 76.7 | I82: 84.7 | J82: Fastest OSM road route
A83: 79 | B83: Raionul Căuşeni | C83: Săiţi | D83: 2729000 | E83: 1174 | F83: RBM09 | G83: or. Căuşeni | H83: 86.8 | I83: 93.1 | J83: Fastest OSM road route
A84: 80 | B84: Raionul Căuşeni | C84: Tănătari | D84: 2732000 | E84: 1676 | F84: RBM09 | G84: or. Căuşeni | H84: 72.5 | I84: 74.9 | J84: Fastest OSM road route
A85: 81 | B85: Raionul Căuşeni | C85: Ursoaia | D85: 2736000 | E85: 1777 | F85: RBM09 | G85: or. Căuşeni | H85: 73.8 | I85: 76.3 | J85: Fastest OSM road route
A86: 82 | B86: Raionul Căușeni | C86: Кицканский сельский совет | E86: 0 | F86: RBM09 | G86: or. Căuşeni | H86: 83.1 | I86: 89.7 | J86: Fastest OSM road route
...

Sheet Balti-North
A1: RBR02 · Bălți–North
A2: Preferred scenario: right-bank / government-administered territory, 2024 population reference
A4: No. | B4: District / municipality | C4: Territorial unit | D4: CUATM | E4: Population 2024 | F4: Micro-region ID | G4: Micro-region centre | H4: Travel time to regional anchor (min) | I4: Route distance to regional anchor (km) | J4: Route calculation
A5: 1 | B5: Drochia | C5: com. Hăsnăşenii Noi | D5: 3619000 | E5: 1098 | F5: RBM01 | G5: Bălți | H5: 14.7 | I5: 15.5 | J5: Fastest OSM road route
A6: 2 | B6: Drochia | C6: com. Petreni | D6: 3629000 | E6: 643 | F6: RBM11 | G6: or. Drochia | H6: 26.6 | I6: 31.3 | J6: Fastest OSM road route
A7: 3 | B7: Drochia | C7: com. Pеlinia | D7: 3627000 | E7: 4913 | F7: RBM11 | G7: or. Drochia | H7: 22.8 | I7: 22.7 | J7: Fastest OSM road route
A8: 4 | B8: Drochia | C8: Dominteni | D8: 3614000 | E8: 745 | F8: RBM11 | G8: or. Drochia | H8: 31.1 | I8: 35 | J8: Fastest OSM road route
A9: 5 | B9: Drochia | C9: Gribova | D9: 3616000 | E9: 1194 | F9: RBM11 | G9: or. Drochia | H9: 32.2 | I9: 37.7 | J9: Fastest OSM road route
A10: 6 | B10: Drochia | C10: Hăsnăşenii Mari | D10: 3618000 | E10: 1056 | F10: RBM11 | G10: or. Drochia | H10: 23.8 | I10: 28.1 | J10: Fastest OSM road route
A11: 7 | B11: Drochia | C11: Miciurin | D11: 3621000 | E11: 888 | F11: RBM11 | G11: or. Drochia | H11: 33.4 | I11: 35.9 | J11: Fastest OSM road route
A12: 8 | B12: Drochia | C12: Moara de Piatră | D12: 3623000 | E12: 876 | F12: RBM01 | G12: Bălți | H12: 20.7 | I12: 23.1 | J12: Fastest OSM road route
A13: 9 | B13: Drochia | C13: Nicoreni | D13: 3624000 | E13: 1958 | F13: RBM27 | G13: or. Rîşcani | H13: 35.5 | I13: 40.5 | J13: Fastest OSM road route
A14: 10 | B14: Drochia | C14: Ochiul Alb | D14: 3625000 | E14: 1853 | F14: RBM11 | G14: or. Drochia | H14: 39.5 | I14: 45 | J14: Fastest OSM road route
A15: 11 | B15: Drochia | C15: Sofia | D15: 3632000 | E15: 2798 | F15: RBM11 | G15: or. Drochia | H15: 31.5 | I15: 32 | J15: Fastest OSM road route
A16: 12 | B16: Mun. Bălți | C16: Bălţi | D16: 301000 | E16: 90954 | F16: RBM01 | G16: Bălți | H16: 2.2 | I16: 1.4 | J16: Fastest OSM road route
... A20: 16 | B20: Raionul Briceni | C20: Beleavinţi | D20: 1411000 | E20: 1284 | F20: RBM26 | G20: or. Briceni | H20: 84.1 | I20: 114.5 | J20: Fastest OSM road route
A21: 17 | B21: Raionul Briceni | C21: Berlinți | E21: 0 | F21: RBM26 | G21: or. Briceni | H21: 83.6 | I21: 112.5 | J21: Fastest OSM road route
A22: 18 | B22: Raionul Briceni | C22: Bulboaca | D22: 1415000 | E22: 509 | F22: RBM26 | G22: or. Briceni | H22: 80.7 | I22: 103.6 | J22: Fastest OSM road route
A23: 19 | B23: Raionul Briceni | C23: Caracuşenii Vechi | D23: 1416000 | E23: 2629 | F23: RBM26 | G23: or. Briceni | H23: 76.4 | I23: 97.5 | J23: Fastest OSM road route
A24: 20 | B24: Raionul Briceni | C24: com. Bălcăuţi | D24: 1412000 | E24: 339 | F24: RBM26 | G24: or. Briceni | H24: 66.5 | I24: 88.4 | J24: Fastest OSM road route
A25: 21 | B25: Raionul Briceni | C25: com. Berlinţi | D25: 1413000 | E25: 1136 | F25: RBM26 | G25: or. Briceni | H25: 76.3 | I25: 104.1 | J25: Fastest OSM road route
A26: 22 | B26: Raionul Briceni | C26: com. Bogdăneşti | D26: 1414000 | E26: 891 | F26: RBM13 | G26: or. Edineţ | H26: 75.6 | I26: 96.5 | J26: Fastest OSM road route
A27: 23 | B27: Raionul Briceni | C27: com. Colicăuţi | D27: 1417000 | E27: 2025 | F27: RBM26 | G27: or. Briceni | H27: 72.1 | I27: 93.5 | J27: Fastest OSM road route
A28: 24 | B28: Raionul Briceni | C28: com. Halahora de Sus | D28: 1424000 | E28: 951 | F28: RBM26 | G28: or. Briceni | H28: 64.8 | I28: 86.4 | J28: Fastest OSM road route
A29: 25 | B29: Raionul Briceni | C29: com. Larga | D29: 1426000 | E29: 2977 | F29: RBM26 | G29: or. Briceni | H29: 92.5 | I29: 119.9 | J29: Fastest OSM road route
A30: 26 | B30: Raionul Briceni | C30: com. Mărcăuţi | D30: 1427000 | E30: 863 | F30: RBM26 | G30: or. Briceni | H30: 70.4 | I30: 92.5 | J30: Fastest OSM road route
A31: 27 | B31: Raionul Briceni | C31: com. Medveja | D31: 1428000 | E31: 885 | F31: RBM26 | G31: or. Briceni | H31: 97.3 | I31: 126 | J31: Fastest OSM road route
A32: 28 | B32: Raionul Briceni | C32: com. Mihăileni | D32: 1429000 | E32: 392 | F32: RBM13 | G32: or. Edineţ | H32: 64.5 | I32: 84.3 | J32: Fastest OSM road route
A33: 29 | B33: Raionul Briceni | C33: Corjeuţi | D33: 1418000 | E33: 4495 | F33: RBM26 | G33: or. Briceni | H33: 75 | I33: 95.8 | J33: Fastest OSM road route
... A38: 34 | B38: Raionul Briceni | C38: Grimăncăuţi | D38: 1423000 | E38: 2854 | F38: RBM26 | G38: or. Briceni | H38: 77.3 | I38: 102.9 | J38: Fastest OSM road route
A39: 35 | B39: Raionul Briceni | C39: Grimăncăuți | E39: 0 | F39: RBM26 | G39: or. Briceni | H39: 75.6 | I39: 102.2 | J39: Fastest OSM road route
A40: 36 | B40: Raionul Briceni | C40: Hlina | D40: 1425000 | E40: 647 | F40: RBM26 | G40: or. Briceni | H40: 87 | I40: 119.2 | J40: Fastest OSM road route
A41: 37 | B41: Raionul Briceni | C41: or. Briceni | D41: 1401000 | E41: 5785 | F41: RBM26 | G41: or. Briceni | H41: 73.6 | I41: 99.8 | J41: Fastest OSM road route
A42: 38 | B42: Raionul Briceni | C42: or. Lipcani | D42: 1402000 | E42: 3569 | F42: RBM26 | G42: or. Briceni | H42: 91.7 | I42: 124.9 | J42: Fastest OSM road route
A43: 39 | B43: Raionul Briceni | C43: Pererita | D43: 1430000 | E43: 939 | F43: RBM26 | G43: or. Briceni | H43: 83 | I43: 105.5 | J43: Fastest OSM road route
A44: 40 | B44: Raionul Briceni | C44: Slobozia-Şirăuţi | D44: 1431000 | E44: 689 | F44: RBM26 | G44: or. Briceni | H44: 87.4 | I44: 108.9 | J44: Fastest OSM road route
A45: 41 | B45: Raionul Briceni | C45: Şirăuţi | D45: 1432000 | E45: 1217 | F45: RBM26 | G45: or. Briceni | H45: 89.9 | I45: 113.3 | J45: Fastest OSM road route
A46: 42 | B46: Raionul Briceni | C46: Tabani | D46: 1433000 | E46: 1807 | F46: RBM26 | G46: or. Briceni | H46: 71.6 | I46: 95.9 | J46: Fastest OSM road route
A47: 43 | B47: Raionul Briceni | C47: Teţcani | D47: 1434000 | E47: 1701 | F47: RBM26 | G47: or. Briceni | H47: 79.9 | I47: 101.9 | J47: Fastest OSM road route
A48: 44 | B48: Raionul Briceni | C48: Trebisăuţi | D48: 1435000 | E48: 1299 | F48: RBM26 | G48: or. Briceni | H48: 77.8 | I48: 104.6 | J48: Fastest OSM road route
...

Sheet Ungheni-West
A1: RBR03 · Ungheni–West
A2: Preferred scenario: right-bank / government-administered territory, 2024 population reference
A4: No. | B4: District / municipality | C4: Territorial unit | D4: CUATM | E4: Population 2024 | F4: Micro-region ID | G4: Micro-region centre | H4: Travel time to regional anchor (min) | I4: Route distance to regional anchor (km) | J4: Route calculation
A5: 1 | B5: Raionul Călăraşi | C5: com. Bahmut | D5: 2510000 | E5: 1121 | F5: RBM18 | G5: or. Călăraşi | H5: 30.1 | I5: 38.4 | J5: Fastest OSM road route
A6: 2 | B6: Raionul Călăraşi | C6: com. Sipoteni | D6: 2530000 | E6: 4491 | F6: RBM18 | G6: or. Călăraşi | H6: 34.9 | I6: 44.9 | J6: Fastest OSM road route
A7: 3 | B7: Raionul Făleşti | C7: com. Ciolacu Nou | D7: 4315000 | E7: 1615 | F7: RBM08 | G7: or. Făleşti | H7: 35.3 | I7: 42.2 | J7: Fastest OSM road route
A8: 4 | B8: Raionul Făleşti | C8: com. Horeşti | D8: 4320000 | E8: 642 | F8: RBM08 | G8: or. Făleşti | H8: 30.8 | I8: 37.9 | J8: Fastest OSM road route
A9: 5 | B9: Raionul Făleşti | C9: com. Taxobeni | D9: 4339000 | E9: 1069 | F9: RBM33 | G9: com. Sculeni | H9: 27.5 | I9: 32 | J9: Fastest OSM road route
A10: 6 | B10: Raionul Făleşti | C10: Izvoare | D10: 4323000 | E10: 1262 | F10: RBM08 | G10: or. Făleşti | H10: 33.5 | I10: 39.2 | J10: Fastest OSM road route
A11: 7 | B11: Raionul Hînceşti | C11: Călmăţui | D11: 5317000 | E11: 1048 | F11: RBM22 | G11: or. Leova | H11: 66.5 | I11: 72.6 | J11: Fastest OSM road route
A12: 8 | B12: Raionul Hînceşti | C12: Căţeleni | D12: 5319000 | E12: 705 | F12: RBM14 | G12: or. Nisporeni | H12: 53 | I12: 55.1 | J12: Fastest OSM road route
A13: 9 | B13: Raionul Hînceşti | C13: com. Cotul Morii | D13: 5322000 | E13: 1196 | F13: RBM14 | G13: or. Nisporeni | H13: 57.1 | I13: 60.2 | J13: Fastest OSM road route
A14: 10 | B14: Raionul Hînceşti | C14: com. Ivanovca | D14: 5328000 | E14: 645 | F14: RBM14 | G14: or. Nisporeni | H14: 59.1 | I14: 61 | J14: Fastest OSM road route
A15: 11 | B15: Raionul Hînceşti | C15: com. Leuşeni | D15: 5330000 | E15: 1209 | F15: RBM22 | G15: or. Leova | H15: 62.4 | I15: 66.8 | J15: Fastest OSM road route
A16: 12 | B16: Raionul Hînceşti | C16: Dancu | D16: 5324000 | E16: 860 | F16: RBM22 | G16: or. Leova | H16: 70.2 | I16: 75.9 | J16: Fastest OSM road route
... A59: 55 | B59: Raionul Ungheni | C59: com. Zagarancea | D59: 9240000 | E59: 2906 | F59: RBM03 | G59: or. Ungheni | H59: 7.7 | I59: 7.2 | J59: Fastest OSM road route
A60: 56 | B60: Raionul Ungheni | C60: Cornești | E60: 0 | F60: RBM03 | G60: or. Ungheni | H60: 21 | I60: 27 | J60: Fastest OSM road route
A61: 57 | B61: Raionul Ungheni | C61: Cornova | D61: 9221000 | E61: 599 | F61: RBM30 | G61: or. Teleneşti | H61: 43.5 | I61: 48.7 | J61: Fastest OSM road route
A62: 58 | B62: Raionul Ungheni | C62: Costuleni | D62: 9222000 | E62: 2249 | F62: RBM03 | G62: or. Ungheni | H62: 19.9 | I62: 17.9 | J62: Fastest OSM road route
A63: 59 | B63: Raionul Ungheni | C63: Măgurele | D63: 9226000 | E63: 414 | F63: RBM03 | G63: or. Ungheni | H63: 35.3 | I63: 40.9 | J63: Fastest OSM road route
A64: 60 | B64: Raionul Ungheni | C64: Năpădeni | D64: 9229000 | E64: 512 | F64: RBM30 | G64: or. Teleneşti | H64: 43 | I64: 48 | J64: Fastest OSM road route
A65: 61 | B65: Raionul Ungheni | C65: or. Corneşti | D65: 9202000 | E65: 1698 | F65: RBM03 | G65: or. Ungheni | H65: 20.1 | I65: 21.5 | J65: Fastest OSM road route
A66: 62 | B66: Raionul Ungheni | C66: or. Ungheni | D66: 9201000 | E66: 26457 | F66: RBM03 | G66: or. Ungheni | H66: 0 | I66: 0 | J66: Fastest OSM road route
A67: 63 | B67: Raionul Ungheni | C67: Rădenii Vechi | D67: 9233000 | E67: 1027 | F67: RBM03 | G67: or. Ungheni | H67: 24.8 | I67: 26.5 | J67: Fastest OSM road route
A68: 64 | B68: Raionul Ungheni | C68: Teşcureni | D68: 9236000 | E68: 646 | F68: RBM03 | G68: or. Ungheni | H68: 22.1 | I68: 26.8 | J68: Fastest OSM road route
A69: 65 | B69: Raionul Ungheni | C69: Unţeşti | D69: 9238000 | E69: 1127 | F69: RBM03 | G69: or. Ungheni | H69: 14 | I69: 14.1 | J69: Fastest OSM road route

Sheet Soroca-NE
A1: RBR04 · Soroca–North-East
A2: Preferred scenario: right-bank / government-administered territory, 2024 population reference
A4: No. | B4: District / municipality | C4: Territorial unit | D4: CUATM | E4: Population 2024 | F4: Micro-region ID | G4: Micro-region centre | H4: Travel time to regional anchor (min) | I4: Route distance to regional anchor (km) | J4: Route calculation
A5: 1 | B5: Drochia | C5: Antoneuca | D5: 3610000 | E5: 274 | F5: RBM11 | G5: or. Drochia | H5: 43.4 | I5: 52.9 | J5: Fastest OSM road route
A6: 2 | B6: Drochia | C6: Chetrosu | D6: 3612000 | E6: 3388 | F6: RBM11 | G6: or. Drochia | H6: 28.1 | I6: 34.9 | J6: Fastest OSM road route
A7: 3 | B7: Drochia | C7: com. Baroncea | D7: 3611000 | E7: 1028 | F7: RBM11 | G7: or. Drochia | H7: 34.5 | I7: 42 | J7: Fastest OSM road route
A8: 4 | B8: Drochia | C8: com. Cotova | D8: 3613000 | E8: 1785 | F8: RBM11 | G8: or. Drochia | H8: 24.7 | I8: 28.9 | J8: Fastest OSM road route
A9: 5 | B9: Drochia | C9: com. Fîntîniţa | D9: 3617000 | E9: 744 | F9: RBM11 | G9: or. Drochia | H9: 47.3 | I9: 57.7 | J9: Fastest OSM road route
A10: 6 | B10: Drochia | C10: com. Palanca | D10: 3626000 | E10: 485 | F10: RBM11 | G10: or. Drochia | H10: 27.4 | I10: 33 | J10: Fastest OSM road route
A11: 7 | B11: Drochia | C11: com. Pervomaiscoe | D11: 3628000 | E11: 490 | F11: RBM11 | G11: or. Drochia | H11: 46.1 | I11: 55.7 | J11: Fastest OSM road route
A12: 8 | B12: Drochia | C12: com. Şalvirii Vechi | D12: 3633000 | E12: 474 | F12: RBM11 | G12: or. Drochia | H12: 33.1 | I12: 37 | J12: Fastest OSM road route
A13: 9 | B13: Drochia | C13: com. Şuri | D13: 3634000 | E13: 2859 | F13: RBM11 | G13: or. Drochia | H13: 35.1 | I13: 42.6 | J13: Fastest OSM road route
A14: 10 | B14: Drochia | C14: Maramonovca | D14: 3620000 | E14: 1443 | F14: RBM11 | G14: or. Drochia | H14: 42.3 | I14: 45.7 | J14: Fastest OSM road route
A15: 11 | B15: Drochia | C15: Mîndîc | D15: 3622000 | E15: 1899 | F15: RBM11 | G15: or. Drochia | H15: 38.1 | I15: 42.6 | J15: Fastest OSM road route
A16: 12 | B16: Drochia | C16: or. Drochia | D16: 3601000 | E16: 12939 | F16: RBM11 | G16: or. Drochia | H16: 34 | I16: 42.5 | J16: Fastest OSM road route
... A32: 28 | B32: Raionul Donduşeni | C32: Crişcăuţi | D32: 3416000 | E32: 735 | F32: RBM06 | G32: or. Soroca | H32: 35.4 | I32: 40.7 | J32: Fastest OSM road route
A33: 29 | B33: Raionul Dondușeni | C33: Dondușeni | E33: 0 | F33: RBM13 | G33: or. Edineţ | H33: 57.8 | I33: 64.6 | J33: Fastest OSM road route
A34: 30 | B34: Raionul Dondușeni | C34: Dondușeni | E34: 0 | F34: RBM13 | G34: or. Edineţ | H34: 55.6 | I34: 63.5 | J34: Fastest OSM road route
A35: 31 | B35: Raionul Donduşeni | C35: Horodişte | D35: 3419000 | E35: 584 | F35: RBM06 | G35: or. Soroca | H35: 41.3 | I35: 46.5 | J35: Fastest OSM road route
A36: 32 | B36: Raionul Donduşeni | C36: or. Donduşeni | D36: 3401000 | E36: 5987 | F36: RBM13 | G36: or. Edineţ | H36: 57.2 | I36: 64.7 | J36: Fastest OSM road route
A37: 33 | B37: Raionul Donduşeni | C37: Pivniceni | D37: 3421000 | E37: 408 | F37: RBM13 | G37: or. Edineţ | H37: 61.6 | I37: 72.7 | J37: Fastest OSM road route
A38: 34 | B38: Raionul Donduşeni | C38: Plop | D38: 3422000 | E38: 936 | F38: RBM13 | G38: or. Edineţ | H38: 50.9 | I38: 62.8 | J38: Fastest OSM road route
A39: 35 | B39: Raionul Donduşeni | C39: Pocrovca | D39: 3423000 | E39: 940 | F39: RBM06 | G39: or. Soroca | H39: 31.6 | I39: 39.6 | J39: Fastest OSM road route
A40: 36 | B40: Raionul Donduşeni | C40: Rediul Mare | D40: 3424000 | E40: 613 | F40: RBM13 | G40: or. Edineţ | H40: 63.7 | I40: 74.2 | J40: Fastest OSM road route
A41: 37 | B41: Raionul Donduşeni | C41: Scăieni | D41: 3425000 | E41: 1044 | F41: RBM11 | G41: or. Drochia | H41: 54.8 | I41: 61.2 | J41: Fastest OSM road route
A42: 38 | B42: Raionul Donduşeni | C42: Ţaul | D42: 3429000 | E42: 1947 | F42: RBM11 | G42: or. Drochia | H42: 50.8 | I42: 58.1 | J42: Fastest OSM road route
A43: 39 | B43: Raionul Drochia | C43: Drochia | E43: 0 | F43: RBM11 | G43: or. Drochia | H43: 38.1 | I43: 45.6 | J43: Fastest OSM road route
A44: 40 | B44: Raionul Floreşti | C44: Cerniţa | D44: 4514000 | E44: 545 | F44: RBM12 | G44: or. Floreşti | H44: 29.7 | I44: 35.1 | J44: Fastest OSM road route
A45: 41 | B45: Raionul Floreşti | C45: Ciripcău | D45: 4515000 | E45: 681 | F45: RBM12 | G45: or. Floreşti | H45: 20.3 | I45: 26.7 | J45: Fastest OSM road route
A46: 42 | B46: Raionul Floreşti | C46: com. Alexeevca | D46: 4510000 | E46: 704 | F46: RBM12 | G46: or. Floreşti | H46: 27 | I46: 33.1 | J46: Fastest OSM road route
A47: 43 | B47: Raionul Floreşti | C47: com. Cuhureştii de Jos | D47: 4518000 | E47: 1177 | F47: RBM12 | G47: or. Floreşti | H47: 36.8 | I47: 45.4 | J47: Fastest OSM road route
A48: 44 | B48: Raionul Floreşti | C48: com. Cuhureştii de Sus | D48: 4519000 | E48: 1475 | F48: RBM12 | G48: or. Floreşti | H48: 32.9 | I48: 40.8 | J48: Fastest OSM road route
A49: 45 | B49: Raionul Floreşti | C49: com. Gura Camencii | D49: 4524000 | E49: 2232 | F49: RBM12 | G49: or. Floreşti | H49: 25.4 | I49: 33.7 | J49: Fastest OSM road route
A50: 46 | B50: Raionul Floreşti | C50: com. Izvoare | D50: 4527000 | E50: 1004 | F50: RBM12 | G50: or. Floreşti | H50: 22.9 | I50: 26.6 | J50: Fastest OSM road route
A51: 47 | B51: Raionul Floreşti | C51: com. Japca | D51: 4528000 | E51: 880 | F51: RBM12 | G51: or. Floreşti | H51: 50 | I51: 60.7 | J51: Fastest OSM road route
A52: 48 | B52: Raionul Floreşti | C52: com. Prodăneşti | D52: 4535000 | E52: 1154 | F52: RBM12 | G52: or. Floreşti | H52: 45.2 | I52: 58.3 | J52: Fastest OSM road route
A53: 49 | B53: Raionul Floreşti | C53: com. Trifăneşti | D53: 4544000 | E53: 727 | F53: RBM12 | G53: or. Floreşti | H53: 27.6 | I53: 31.2 | J53: Fastest OSM road route
A54: 50 | B54: Raionul Floreşti | C54: com. Văscăuţi | D54: 4546000 | E54: 503 | F54: RBM12 | G54: or. Floreşti | H54: 38.8 | I54: 29.1 | J54: Straight-line fallback
A55: 51 | B55: Raionul Floreşti | C55: Coşerniţa | D55: 4517000 | E55: 914 | F55: RBM12 | G55: or. Floreşti | H55: 32.6 | I55: 39 | J55: Fastest OSM road route
... A57: 53 | B57: Raionul Floreşti | C57: Domulgeni | D57: 4521000 | E57: 932 | F57: RBM12 | G57: or. Floreşti | H57: 40.8 | I57: 53.5 | J57: Fastest OSM road route
...

Sheet Orhei-Centre-N
A1: RBR05 · Orhei–Centre-North
A2: Preferred scenario: right-bank / government-administered territory, 2024 population reference
A4: No. | B4: District / municipality | C4: Territorial unit | D4: CUATM | E4: Population 2024 | F4: Micro-region ID | G4: Micro-region centre | H4: Travel time to regional anchor (min) | I4: Route distance to regional anchor (km) | J4: Route calculation
A5: 1 | B5: Raionul Călăraşi | C5: Bravicea | D5: 2511000 | E5: 2069 | F5: RBM30 | G5: or. Teleneşti | H5: 33.3 | I5: 39.1 | J5: Fastest OSM road route
A6: 2 | B6: Raionul Călăraşi | C6: com. Dereneu | D6: 2514000 | E6: 738 | F6: RBM30 | G6: or. Teleneşti | H6: 44.2 | I6: 56.1 | J6: Fastest OSM road route
A7: 3 | B7: Raionul Călăraşi | C7: com. Hîrjauca | D7: 2517000 | E7: 1829 | F7: RBM18 | G7: or. Călăraşi | H7: 57.8 | I7: 70.2 | J7: Fastest OSM road route
A8: 4 | B8: Raionul Călăraşi | C8: com. Onişcani | D8: 2522000 | E8: 969 | F8: RBM18 | G8: or. Călăraşi | H8: 44.4 | I8: 57.1 | J8: Fastest OSM road route
A9: 5 | B9: Raionul Călăraşi | C9: com. Răciula | D9: 2526000 | E9: 1433 | F9: RBM18 | G9: or. Călăraşi | H9: 45.8 | I9: 55.9 | J9: Fastest OSM road route
A10: 6 | B10: Raionul Călăraşi | C10: com. Săseni | D10: 2529000 | E10: 1304 | F10: RBM30 | G10: or. Teleneşti | H10: 31.4 | I10: 34 | J10: Fastest OSM road route
A11: 7 | B11: Raionul Călăraşi | C11: com. Ţibirica | D11: 2534000 | E11: 1474 | F11: RBM30 | G11: or. Teleneşti | H11: 35.9 | I11: 45.9 | J11: Fastest OSM road route
A12: 8 | B12: Raionul Călăraşi | C12: Frumoasa | D12: 2515000 | E12: 408 | F12: RBM18 | G12: or. Călăraşi | H12: 46.5 | I12: 55.7 | J12: Fastest OSM road route
A13: 9 | B13: Raionul Călăraşi | C13: Hirova | D13: 2516000 | E13: 780 | F13: RBM30 | G13: or. Teleneşti | H13: 41.7 | I13: 52.8 | J13: Fastest OSM road route
A14: 10 | B14: Raionul Călăraşi | C14: Hogineşti | D14: 2518000 | E14: 1146 | F14: RBM30 | G14: or. Teleneşti | H14: 41.8 | I14: 51.7 | J14: Fastest OSM road route
A15: 11 | B15: Raionul Călăraşi | C15: Meleşeni | D15: 2520000 | E15: 932 | F15: RBM30 | G15: or. Teleneşti | H15: 33.2 | I15: 42.3 | J15: Fastest OSM road route
A16: 12 | B16: Raionul Criuleni | C16: com. Hîrtopul Mare | D16: 3120000 | E16: 2295 | F16: RBM24 | G16: or. Criuleni | H16: 26.5 | I16: 29.7 | J16: Fastest OSM road route
... A24: 20 | B24: Raionul Dubăsari | C24: com. Cocieri | D24: 3810000 | E24: 3068 | F24: RBM24 | G24: or. Criuleni | H24: 41.9 | I24: 31.4 | J24: Straight-line fallback
A25: 21 | B25: Raionul Dubăsari | C25: Corjova / Коржево | E25: 0 | F25: RBM24 | G25: or. Criuleni | H25: 35.7 | I25: 26.8 | J25: Straight-line fallback
A26: 22 | B26: Raionul Dubăsari | C26: Holercani | D26: 3814000 | E26: 1505 | F26: RBM24 | G26: or. Criuleni | H26: 31.5 | I26: 35.4 | J26: Fastest OSM road route
A27: 23 | B27: Raionul Dubăsari | C27: Marcăuţi | D27: 3815000 | E27: 466 | F27: RBM24 | G27: or. Criuleni | H27: 28.1 | I27: 31.4 | J27: Fastest OSM road route
A28: 24 | B28: Raionul Dubăsari | C28: Molovata | D28: 3816000 | E28: 1706 | F28: RBM24 | G28: or. Criuleni | H28: 31.1 | I28: 33.2 | J28: Fastest OSM road route
A29: 25 | B29: Raionul Dubăsari | C29: Molovata Nouă | D29: 3817000 | E29: 1585 | F29: RBM24 | G29: or. Criuleni | H29: 38.2 | I29: 28.7 | J29: Straight-line fallback
A30: 26 | B30: Raionul Dubăsari | C30: Oxentea | D30: 3818000 | E30: 1680 | F30: RBM24 | G30: or. Criuleni | H30: 25.3 | I30: 27.9 | J30: Fastest OSM road route
A31: 27 | B31: Raionul Orhei | C31: Bolohan | D31: 6412000 | E31: 977 | F31: RBM07 | G31: or. Orhei | H31: 10.7 | I31: 9.9 | J31: Fastest OSM road route
A32: 28 | B32: Raionul Orhei | C32: Brăviceni | D32: 6413000 | E32: 1384 | F32: RBM07 | G32: or. Orhei | H32: 14.5 | I32: 15.7 | J32: Fastest OSM road route
A33: 29 | B33: Raionul Orhei | C33: Bulăieşti | D33: 6414000 | E33: 1067 | F33: RBM07 | G33: or. Orhei | H33: 23.7 | I33: 24.3 | J33: Fastest OSM road route
A34: 30 | B34: Raionul Orhei | C34: Clişova | D34: 6417000 | E34: 679 | F34: RBM30 | G34: or. Teleneşti | H34: 26.1 | I34: 29.7 | J34: Fastest OSM road route
A35: 31 | B35: Raionul Orhei | C35: com. Berezlogi | D35: 6410000 | E35: 1292 | F35: RBM07 | G35: or. Orhei | H35: 18.4 | I35: 19.1 | J35: Fastest OSM road route
A36: 32 | B36: Raionul Orhei | C36: com. Bieşti | D36: 6411000 | E36: 1675 | F36: RBM07 | G36: or. Orhei | H36: 27 | I36: 25.3 | J36: Fastest OSM road route
A37: 33 | B37: Raionul Orhei | C37: com. Chiperceni | D37: 6415000 | E37: 1982 | F37: RBM07 | G37: or. Orhei | H37: 20.5 | I37: 19.7 | J37: Fastest OSM road route
... A98: 94 | B98: Raionul Străşeni | C98: Oneşti | D98: 8022000 | E98: 532 | F98: RBM07 | G98: or. Orhei | H98: 28.5 | I98: 32.5 | J98: Fastest OSM road route
A99: 95 | B99: Raionul Strășeni | C99: Recea | E99: 0 | F99: RBM07 | G99: or. Orhei | H99: 27.3 | I99: 30.8 | J99: Fastest OSM road route
A100: 96 | B100: Raionul Strășeni | C100: Recea | E100: 0 | F100: RBM07 | G100: or. Orhei | H100: 27.5 | I100: 31.1 | J100: Fastest OSM road route
A101: 97 | B101: Raionul Străşeni | C101: Romăneşti | D101: 8026000 | E101: 972 | F101: RBM07 | G101: or. Orhei | H101: 22.9 | I101: 24.6 | J101: Fastest OSM road route
A102: 98 | B102: Raionul Străşeni | C102: Ţigăneşti | D102: 8031000 | E102: 982 | F102: RBM07 | G102: or. Orhei | H102: 28.1 | I102: 32.1 | J102: Fastest OSM road route
A103: 99 | B103: Raionul Străşeni | C103: Voinova | D103: 8032000 | E103: 985 | F103: RBM18 | G103: or. Călăraşi | H103: 39.8 | I103: 46.8 | J103: Fastest OSM road route
A104: 100 | B104: Raionul Străşeni | C104: Zubreşti | D104: 8034000 | E104: 2093 | F104: RBM18 | G104: or. Călăraşi | H104: 33.4 | I104: 39.5 | J104: Fastest OSM road route
A105: 101 | B105: Raionul Şoldăneşti | C105: com. Alcedar | D105: 8310000 | E105: 803 | F105: RBM12 | G105: or. Floreşti | H105: 59.7 | I105: 74 | J105: Fastest OSM road route
A106: 102 | B106: Raionul Şoldăneşti | C106: Cuşmirca | D106: 8315000 | E106: 1359 | F106: RBM12 | G106: or. Floreşti | H106: 61.2 | I106: 74.3 | J106: Fastest OSM road route
A107: 103 | B107: Raionul Şoldăneşti | C107: Fuzăuca | D107: 8317000 | E107: 464 | F107: RBM12 | G107: or. Floreşti | H107: 49.3 | I107: 57 | J107: Fastest OSM road route
A108: 104 | B108: Raionul Şoldăneşti | C108: Găuzeni | D108: 8318000 | E108: 908 | F108: RBM12 | G108: or. Floreşti | H108: 57.4 | I108: 65 | J108: Fastest OSM road route
...

Sheet Cahul-SW
A1: RBR06 · Cahul–South-West
A2: Preferred scenario: right-bank / government-administered territory, 2024 population reference
A4: No. | B4: District / municipality | C4: Territorial unit | D4: CUATM | E4: Population 2024 | F4: Micro-region ID | G4: Micro-region centre | H4: Travel time to regional anchor (min) | I4: Route distance to regional anchor (km) | J4: Route calculation
A5: 1 | B5: Raionul Cahul | C5: Alexanderfeld* | D5: 1710000 | E5: 831 | F5: RBM20 | G5: or. Vulcăneşti | H5: 21.8 | I5: 25.5 | J5: Fastest OSM road route
A6: 2 | B6: Raionul Cahul | C6: Alexandru Ioan Cuza | D6: 1711000 | E6: 1714 | F6: RBM20 | G6: or. Vulcăneşti | H6: 33.8 | I6: 43.1 | J6: Fastest OSM road route
A7: 3 | B7: Raionul Cahul | C7: Andruşul de Jos | D7: 1712000 | E7: 1457 | F7: RBM04 | G7: or. Cahul | H7: 12.2 | I7: 11.1 | J7: Fastest OSM road route
A8: 4 | B8: Raionul Cahul | C8: Andruşul de Sus | D8: 1713000 | E8: 1071 | F8: RBM04 | G8: or. Cahul | H8: 8.9 | I8: 9.2 | J8: Fastest OSM road route
A9: 5 | B9: Raionul Cahul | C9: Badicul Moldovenesc | D9: 1714000 | E9: 776 | F9: RBM04 | G9: or. Cahul | H9: 26.6 | I9: 27.9 | J9: Fastest OSM road route
A10: 6 | B10: Raionul Cahul | C10: Baurci-Moldoveni | D10: 1715000 | E10: 1285 | F10: RBM04 | G10: or. Cahul | H10: 21.8 | I10: 20.8 | J10: Fastest OSM road route
A11: 7 | B11: Raionul Cahul | C11: Brînza | D11: 1715200 | E11: 1398 | F11: RBM20 | G11: or. Vulcăneşti | H11: 38.3 | I11: 32.1 | J11: Fastest OSM road route
A12: 8 | B12: Raionul Cahul | C12: Bucuria | D12: 1716000 | E12: 383 | F12: RBM04 | G12: or. Cahul | H12: 11.7 | I12: 14.5 | J12: Fastest OSM road route
A13: 9 | B13: Raionul Cahul | C13: Cîşliţa-Prut | D13: 1721000 | E13: 812 | F13: RBM20 | G13: or. Vulcăneşti | H13: 42.7 | I13: 57.1 | J13: Fastest OSM road route
A14: 10 | B14: Raionul Cahul | C14: Colibaşi | D14: 1722000 | E14: 3053 | F14: RBM20 | G14: or. Vulcăneşti | H14: 37.5 | I14: 47.6 | J14: Fastest OSM road route
A15: 11 | B15: Raionul Cahul | C15: com. Burlacu | D15: 1717000 | E15: 1172 | F15: RBM04 | G15: or. Cahul | H15: 27.2 | I15: 31.2 | J15: Fastest OSM road route
A16: 12 | B16: Raionul Cahul | C16: com. Burlăceni | D16: 1718000 | E16: 1228 | F16: RBM20 | G16: or. Vulcăneşti | H16: 33.5 | I16: 45.8 | J16: Fastest OSM road route
... A69: 65 | B69: Unitatea Teritorială Autonomă Găgăuzia | C69: or. Vulcăneşti | D69: 9603000 | E69: 10919 | F69: RBM20 | G69: or. Vulcăneşti | H69: 26.4 | I69: 34.1 | J69: Fastest OSM road route

Sheet Comrat-SE
A1: RBR07 · Comrat–South-East
A2: Preferred scenario: right-bank / government-administered territory, 2024 population reference
A4: No. | B4: District / municipality | C4: Territorial unit | D4: CUATM | E4: Population 2024 | F4: Micro-region ID | G4: Micro-region centre | H4: Travel time to regional anchor (min) | I4: Route distance to regional anchor (km) | J4: Route calculation
A5: 1 | B5: Raionul Basarabeasca | C5: Abaclia | D5: 1210000 | E5: 2856 | F5: RBM21 | G5: or. Basarabeasca | H5: 22 | I5: 26.9 | J5: Fastest OSM road route
A6: 2 | B6: Raionul Basarabeasca | C6: Başcalia | D6: 1211000 | E6: 1311 | F6: RBM05 | G6: or. Comrat | H6: 18.1 | I6: 19.7 | J6: Fastest OSM road route
A7: 3 | B7: Raionul Basarabeasca | C7: Carabetovca | D7: 1212000 | E7: 971 | F7: RBM21 | G7: or. Basarabeasca | H7: 33.8 | I7: 41.8 | J7: Fastest OSM road route
A8: 4 | B8: Raionul Basarabeasca | C8: com. Iserlia | D8: 1214000 | E8: 628 | F8: RBM17 | G8: or. Cimişlia | H8: 39.4 | I8: 45.1 | J8: Fastest OSM road route
A9: 5 | B9: Raionul Basarabeasca | C9: Iordanovca | D9: 1213000 | E9: 434 | F9: RBM21 | G9: or. Basarabeasca | H9: 31.3 | I9: 39.1 | J9: Fastest OSM road route
A10: 6 | B10: Raionul Basarabeasca | C10: or. Basarabeasca | D10: 1201000 | E10: 6291 | F10: RBM21 | G10: or. Basarabeasca | H10: 27.8 | I10: 34.5 | J10: Fastest OSM road route
A11: 7 | B11: Raionul Basarabeasca | C11: Sadaclia | D11: 1215000 | E11: 2423 | F11: RBM17 | G11: or. Cimişlia | H11: 34 | I11: 39.6 | J11: Fastest OSM road route
A12: 8 | B12: Raionul Cahul | C12: Borceag | D12: 1715100 | E12: 1001 | F12: RBM31 | G12: Congaz | H12: 30.1 | I12: 37.7 | J12: Fastest OSM road route
A13: 9 | B13: Raionul Cahul | C13: com. Chioselia Mare | D13: 1720000 | E13: 1074 | F13: RBM31 | G13: Congaz | H13: 35.2 | I13: 41.2 | J13: Fastest OSM road route
A14: 10 | B14: Raionul Cantemir | C14: Capaclia | D14: 2113000 | E14: 999 | F14: RBM34 | G14: or. Cantemir | H14: 25.4 | I14: 29.3 | J14: Fastest OSM road route
A15: 11 | B15: Raionul Cantemir | C15: Cîrpeşti | D15: 2117000 | E15: 1257 | F15: RBM34 | G15: or. Cantemir | H15: 38.5 | I15: 40.4 | J15: Fastest OSM road route
A16: 12 | B16: Raionul Cantemir | C16: Cociulia | D16: 2119000 | E16: 1797 | F16: RBM34 | G16: or. Cantemir | H16: 23.9 | I16: 26.9 | J16: Fastest OSM road route
... A100: 96 | B100: Unitatea Teritorială Autonomă Găgăuzia | C100: Tomai | D100: 9632000 | E100: 3026 | F100: RBM15 | G100: or. Ceadîr-Lunga | H100: 21.8 | I100: 23.9 | J100: Fastest OSM road route
